Workbook

Sheet Panel
B1: CeraLux · Creativos
B2: Qué anuncio, qué hook y qué cuerpo te están dando dinero. Datos de Meta corregidos con tus pedidos reales.
B3: Desde | C3: =FECHA_INICIO -> 46300 | E3: Hasta | F3: =TODAY() -> 46302 | H3: Días | I3: =MAX(1,F3-C3+1) -> 3 | J3: Actualizado: 2026-10-07 20:50
B5: RESUMEN DEL PERIODO
B6: GASTO | D6: COMPRAS (META) | F6: PEDIDOS REALES | H6: PEDIDOS REALES ÷ META | J6: CPA REAL | L6: BENEFICIO ESTIMADO
B7: =SUMIFS(Histórico!$F$5:$F$5000,Histórico!$A$5:$A$5000,">="&DESDE,Histórico!$A$5:$A$5000,"<="&HASTA) -> 175.21 | D7: =SUMIFS(Histórico!$L$5:$L$5000,Histórico!$A$5:$A$5000,">="&DESDE,Histórico!$A$5:$A$5000,"<="&HASTA) -> 21 | F7: =IF(SUMIFS(Pedidos!$B$5:$B$7,Pedidos!$A$5:$A$7,">="&DESDE,Pedidos!$A$5:$A$7,"<="&HASTA)>0,SUMIFS(Pedidos!$B$5:$B$7,Pedidos!$A$5:$A$7,">="&DESDE,Pedidos!$A$5:$A$7,"<="&HASTA),D7) -> 22 | H7: =IF(D7>0,F7/D7,1) -> 1.047619 | J7: =IF(F7>0,B7/F7,"") -> 7.9640909 | L7: =F7*BEN_PEDIDO-B7*(1+RECARGO) -> 83.51
B9: CPA MÁXIMO RENTABLE | D9: GANCHO MEDIO (25%) | F9: CTR MEDIO | H9: LLEGA A LA WEB | J9: COMPRA / CLIC | L9: ANUNCIOS CON GASTO
B10: =CPA_BE -> 11.76 | D10: =IFERROR(SUMIFS(Histórico!$M$5:$M$5000,Histórico!$A$5:$A$5000,">="&DESDE,Histórico!$A$5:$A$5000,"<="&HASTA)/SUMIFS(Histórico!$G$5:$G$5000,Histórico!$A$5:$A$5000,">="&DESDE,Histórico!$A$5:$A$5000,"<="&HASTA),0) -> 0.13795424 | F10: =IFERROR(SUMIFS(Histórico!$H$5:$H$5000,Histórico!$A$5:$A$5000,">="&DESDE,Histórico!$A$5:$A$5000,"<="&HASTA)/SUMIFS(Histórico!$G$5:$G$5000,Histórico!$A$5:$A$5000,">="&DESDE,Histórico!$A$5:$A$5000,"<="&HASTA),0) -> 0.018932257 | H10: =IFERROR(SUMIFS(Histórico!$I$5:$I$5000,Histórico!$A$5:$A$5000,">="&DESDE,Histórico!$A$5:$A$5000,"<="&HASTA)/SUMIFS(Histórico!$H$5:$H$5000,Histórico!$A$5:$A$5000,">="&DESDE,Histórico!$A$5:$A$5000,"<="&HASTA),0) -> 0.38862559 | J10: =IFERROR(SUMIFS(Histórico!$L$5:$L$5000,Histórico!$A$5:$A$5000,">="&DESDE,Histórico!$A$5:$A$5000,"<="&HASTA)/SUMIFS(Histórico!$H$5:$H$5000,Histórico!$A$5:$A$5000,">="&DESDE,Histórico!$A$5:$A$5000,"<="&HASTA),0) -> 0.049763033 | L10: =COUNTIF(Creativos!$M$5:$M$16,">0") -> 12
B12: QUÉ HACER CON TUS ANUNCIOS
B13: ESCALAR | D13: MANTENER | F13: PROMETEDOR | H13: VIGILAR | J13: APAGAR | L13: APRENDIENDO
B14: =COUNTIF(Creativos!$AA$5:$AA$16,"ESCALAR") -> 2 | D14: =COUNTIF(Creativos!$AA$5:$AA$16,"MANTENER") -> 0 | F14: =COUNTIF(Creativos!$AA$5:$AA$16,"PROMETEDOR") -> 2 | H14: =COUNTIF(Creativos!$AA$5:$AA$16,"VIGILAR") -> 2 | J14: =COUNTIF(Creativos!$AA$5:$AA$16,"APAGAR") -> 0 | L14: =COUNTIF(Creativos!$AA$5:$AA$16,"APRENDIENDO") -> 6
B16: TOP 5 CREATIVOS POR BENEFICIO ESTIMADO
B17: # | C17: Anuncio | E17: Ángulo | G17: Hook | J17: Gasto | K17: CPA real | L17: Beneficio | M17: Veredicto
B18: 1 | C18: =IFERROR(INDEX(Creativos!$B$5:$B$16,MATCH(LARGE(Creativos!$AC$5:$AC$16,1),Creativos!$AC$5:$AC$16,0)),"") -> BROAD_H1 BOLARDO | E18: =IFERROR(INDEX(Creativos!$D$5:$D$16,MATCH(LARGE(Creativos!$AC$5:$AC$16,1),Creativos!$AC$5:$AC$16,0)),"") -> AS3 · BROAD — hooks visuales | G18: =IFERROR(IF(INDEX(Creativos!$I$5:$I$16,MATCH(LARGE(Creativos!$AC$5:$AC$16,1),Creativos!$AC$5:$AC$16,0))="","[visual] "&INDEX(Creativos!$H$5:$H$16,MATCH(LARGE(Creativos!$AC$5:$AC$16,1),Creativos!$AC$5:$AC$16,0)),INDEX(Creativos!$I$5:$I$16,MATCH(LARGE(Creativos!$AC$5:$AC$16,1),Creativos!$AC$5:$AC$16,0))),"") -> [visual] Bolardo | J18: =IFERROR(INDEX(Creativos!$M$5:$M$16,MATCH(LARGE(Creativos!$AC$5:$AC$16,1),Creativos!$AC$5:$AC$16,0)),"") -> 85.54 | K18: =IFERROR(INDEX(Creativos!$S$5:$S$16,MATCH(LARGE(Creativos!$AC$5:$AC$16,1),Creativos!$AC$5:$AC$16,0)),"") -> 8.1651818 | L18: =IFERROR(INDEX(Creativos!$T$5:$T$16,MATCH(LARGE(Creativos!$AC$5:$AC$16,1),Creativos!$AC$5:$AC$16,0)),"") -> 37.66 | M18: =IFERROR(INDEX(Creativos!$AA$5:$AA$16,MATCH(LARGE(Creativos!$AC$5:$AC$16,1),Creativos!$AC$5:$AC$16,0)),"") -> ESCALAR
B19: 2 | C19: =IFERROR(INDEX(Creativos!$B$5:$B$16,MATCH(LARGE(Creativos!$AC$5:$AC$16,2),Creativos!$AC$5:$AC$16,0)),"") -> BROAD_H2 LLAVES | E19: =IFERROR(INDEX(Creativos!$D$5:$D$16,MATCH(LARGE(Creativos!$AC$5:$AC$16,2),Creativos!$AC$5:$AC$16,0)),"") -> AS3 · BROAD — hooks visuales | G19: =IFERROR(IF(INDEX(Creativos!$I$5:$I$16,MATCH(LARGE(Creativos!$AC$5:$AC$16,2),Creativos!$AC$5:$AC$16,0))="","[visual] "&INDEX(Creativos!$H$5:$H$16,MATCH(LARGE(Creativos!$AC$5:$AC$16,2),Creativos!$AC$5:$AC$16,0)),INDEX(Creativos!$I$5:$I$16,MATCH(LARGE(Creativos!$AC$5:$AC$16,2),Creativos!$AC$5:$AC$16,0))),"") -> [visual] Llaves | J19: =IFERROR(INDEX(Creativos!$M$5:$M$16,MATCH(LARGE(Creativos!$AC$5:$AC$16,2),Creativos!$AC$5:$AC$16,0)),"") -> 37.7 | K19: =IFERROR(INDEX(Creativos!$S$5:$S$16,MATCH(LARGE(Creativos!$AC$5:$AC$16,2),Creativos!$AC$5:$AC$16,0)),"") -> 5.9977273 | L19: =IFERROR(INDEX(Creativos!$T$5:$T$16,MATCH(LARGE(Creativos!$AC$5:$AC$16,2),Creativos!$AC$5:$AC$16,0)),"") -> 36.22 | M19: =IFERROR(INDEX(Creativos!$AA$5:$AA$16,MATCH(LARGE(Creativos!$AC$5:$AC$16,2),Creativos!$AC$5:$AC$16,0)),"") -> ESCALAR
B20: 3 | C20: =IFERROR(INDEX(Creativos!$B$5:$B$16,MATCH(LARGE(Creativos!$AC$5:$AC$16,3),Creativos!$AC$5:$AC$16,0)),"") -> BROAD_H4 PERRO | E20: =IFERROR(INDEX(Creativos!$D$5:$D$16,MATCH(LARGE(Creativos!$AC$5:$AC$16,3),Creativos!$AC$5:$AC$16,0)),"") -> AS3 · BROAD — hooks visuales | G20: =IFERROR(IF(INDEX(Creativos!$I$5:$I$16,MATCH(LARGE(Creativos!$AC$5:$AC$16,3),Creativos!$AC$5:$AC$16,0))="","[visual] "&INDEX(Creativos!$H$5:$H$16,MATCH(LARGE(Creativos!$AC$5:$AC$16,3),Creativos!$AC$5:$AC$16,0)),INDEX(Creativos!$I$5:$I$16,MATCH(LARGE(Creativos!$AC$5:$AC$16,3),Creativos!$AC$5:$AC$16,0))),"") -> [visual] Perro | J20: =IFERROR(INDEX(Creativos!$M$5:$M$16,MATCH(LARGE(Creativos!$AC$5:$AC$16,3),Creativos!$AC$5:$AC$16,0)),"") -> 8.45 | K20: =IFERROR(INDEX(Creativos!$S$5:$S$16,MATCH(LARGE(Creativos!$AC$5:$AC$16,3),Creativos!$AC$5:$AC$16,0)),"") -> 4.0329545 | L20: =IFERROR(INDEX(Creativos!$T$5:$T$16,MATCH(LARGE(Creativos!$AC$5:$AC$16,3),Creativos!$AC$5:$AC$16,0)),"") -> 16.19 | M20: =IFERROR(INDEX(Creativos!$AA$5:$AA$16,MATCH(LARGE(Creativos!$AC$5:$AC$16,3),Creativos!$AC$5:$AC$16,0)),"") -> PROMETEDOR
B21: 4 | C21: =IFERROR(INDEX(Creativos!$B$5:$B$16,MATCH(LARGE(Creativos!$AC$5:$AC$16,4),Creativos!$AC$5:$AC$16,0)),"") -> PIXARSUPER_H1 | E21: =IFERROR(INDEX(Creativos!$D$5:$D$16,MATCH(LARGE(Creativos!$AC$5:$AC$16,4),Creativos!$AC$5:$AC$16,0)),"") -> AS1 · RABIA — no fue culpa mía | G21: =IFERROR(IF(INDEX(Creativos!$I$5:$I$16,MATCH(LARGE(Creativos!$AC$5:$AC$16,4),Creativos!$AC$5:$AC$16,0))="","[visual] "&INDEX(Creativos!$H$5:$H$16,MATCH(LARGE(Creativos!$AC$5:$AC$16,4),Creativos!$AC$5:$AC$16,0)),INDEX(Creativos!$I$5:$I$16,MATCH(LARGE(Creativos!$AC$5:$AC$16,4),Creativos!$AC$5:$AC$16,0))),"") -> Vuelves al coche y ahí está, un rayón nuevo y ni una nota. | J21: =IFERROR(INDEX(Creativos!$M$5:$M$16,MATCH(LARGE(Creativos!$AC$5:$AC$16,4),Creativos!$AC$5:$AC$16,0)),"") -> 10.3 | K21: =IFERROR(INDEX(Creativos!$S$5:$S$16,MATCH(LARGE(Creativos!$AC$5:$AC$16,4),Creativos!$AC$5:$AC$16,0)),"") -> 4.9159091 | L21: =IFERROR(INDEX(Creativos!$T$5:$T$16,MATCH(LARGE(Creativos!$AC$5:$AC$16,4),Creativos!$AC$5:$AC$16,0)),"") -> 14.34 | M21: =IFERROR(INDEX(Creativos!$AA$5:$AA$16,MATCH(LARGE(Creativos!$AC$5:$AC$16,4),Creativos!$AC$5:$AC$16,0)),"") -> PROMETEDOR
B22: 5 | C22: =IFERROR(INDEX(Creativos!$B$5:$B$16,MATCH(LARGE(Creativos!$AC$5:$AC$16,5),Creativos!$AC$5:$AC$16,0)),"") -> BROAD_H5 PERRO | E22: =IFERROR(INDEX(Creativos!$D$5:$D$16,MATCH(LARGE(Creativos!$AC$5:$AC$16,5),Creativos!$AC$5:$AC$16,0)),"") -> AS3 · BROAD — hooks visuales | G22: =IFERROR(IF(INDEX(Creativos!$I$5:$I$16,MATCH(LARGE(Creativos!$AC$5:$AC$16,5),Creativos!$AC$5:$AC$16,0))="","[visual] "&INDEX(Creativos!$H$5:$H$16,MATCH(LARGE(Creativos!$AC$5:$AC$16,5),Creativos!$AC$5:$AC$16,0)),INDEX(Creativos!$I$5:$I$16,MATCH(LARGE(Creativos!$AC$5:$AC$16,5),Creativos!$AC$5:$AC$16,0))),"") -> [visual] Perro | J22: =IFERROR(INDEX(Creativos!$M$5:$M$16,MATCH(LARGE(Creativos!$AC$5:$AC$16,5),Creativos!$AC$5:$AC$16,0)),"") -> 0.05 | K22: =IFERROR(INDEX(Creativos!$S$5:$S$16,MATCH(LARGE(Creativos!$AC$5:$AC$16,5),Creativos!$AC$5:$AC$16,0)),"") | L22: =IFERROR(INDEX(Creativos!$T$5:$T$16,MATCH(LARGE(Creativos!$AC$5:$AC$16,5),Creativos!$AC$5:$AC$16,0)),"") -> -0.05 | M22: =IFERROR(INDEX(Creativos!$AA$5:$AA$16,MATCH(LARGE(Creativos!$AC$5:$AC$16,5),Creativos!$AC$5:$AC$16,0)),"") -> APRENDIENDO
B24: POR ÁNGULO (conjunto de anuncios)
B25: Ángulo | F25: Anuncios | G25: Gasto | H25: Compras Meta | I25: Pedidos est. | J25: CPA real | K25: Beneficio est. | L25: Gancho | M25: CTR
B26: AS1 · RABIA — no fue culpa mía | F26: =COUNTIF(Creativos!$D$5:$D$16,$B26) -> 2 | G26: =SUMIFS(Histórico!$F$5:$F$5000,Histórico!$D$5:$D$5000,$B26,Histórico!$A$5:$A$5000,">="&DESDE,Histórico!$A$5:$A$5000,"<="&HASTA) -> 13.67 | H26: =SUMIFS(Histórico!$L$5:$L$5000,Histórico!$D$5:$D$5000,$B26,Histórico!$A$5:$A$5000,">="&DESDE,Histórico!$A$5:$A$5000,"<="&HASTA) -> 2 | I26: =H26*RATIO -> 2.0952381 | J26: =IF(I26>0,G26/I26,"") -> 6.5243182 | K26: =I26*BEN_PEDIDO-G26*(1+RECARGO) -> 10.97 | L26: =IFERROR(SUMIFS(Histórico!$M$5:$M$5000,Histórico!$D$5:$D$5000,$B26,Histórico!$A$5:$A$5000,">="&DESDE,Histórico!$A$5:$A$5000,"<="&HASTA)/SUMIFS(Histórico!$G$5:$G$5000,Histórico!$D$5:$D$5000,$B26,Histórico!$A$5:$A$5000,">="&DESDE,Histórico!$A$5:$A$5000,"<="&HASTA),"") -> 0.25369458 | M26: =IFERROR(SUMIFS(Histórico!$H$5:$H$5000,Histórico!$D$5:$D$5000,$B26,Histórico!$A$5:$A$5000,">="&DESDE,Histórico!$A$5:$A$5000,"<="&HASTA)/SUMIFS(Histórico!$G$5:$G$5000,Histórico!$D$5:$D$5000,$B26,Histórico!$A$5:$A$5000,">="&DESDE,Histórico!$A$5:$A$5000,"<="&HASTA),"") -> 0.02545156
B27: AS2 · DINERO — voy a vender el coche | F27: =COUNTIF(Creativos!$D$5:$D$16,$B27) -> 3 | G27: =SUMIFS(Histórico!$F$5:$F$5000,Histórico!$D$5:$D$5000,$B27,Histórico!$A$5:$A$5000,">="&DESDE,Histórico!$A$5:$A$5000,"<="&HASTA) -> 14.36 | H27: =SUMIFS(Histórico!$L$5:$L$5000,Histórico!$D$5:$D$5000,$B27,Histórico!$A$5:$A$5000,">="&DESDE,Histórico!$A$5:$A$5000,"<="&HASTA) -> 0 | I27: =H27*RATIO -> 0 | J27: =IF(I27>0,G27/I27,"") | K27: =I27*BEN_PEDIDO-G27*(1+RECARGO) -> -14.36 | L27: =IFERROR(SUMIFS(Histórico!$M$5:$M$5000,Histórico!$D$5:$D$5000,$B27,Histórico!$A$5:$A$5000,">="&DESDE,Histórico!$A$5:$A$5000,"<="&HASTA)/SUMIFS(Histórico!$G$5:$G$5000,Histórico!$D$5:$D$5000,$B27,Histórico!$A$5:$A$5000,">="&DESDE,Histórico!$A$5:$A$5000,"<="&HASTA),"") -> 0.19277108 | M27: =IFERROR(SUMIFS(Histórico!$H$5:$H$5000,Histórico!$D$5:$D$5000,$B27,Histórico!$A$5:$A$5000,">="&DESDE,Histórico!$A$5:$A$5000,"<="&HASTA)/SUMIFS(Histórico!$G$5:$G$5000,Histórico!$D$5:$D$5000,$B27,Histórico!$A$5:$A$5000,">="&DESDE,Histórico!$A$5:$A$5000,"<="&HASTA),"") -> 0.031510658
B28: AS3 · BROAD — hooks visuales | F28: =COUNTIF(Creativos!$D$5:$D$16,$B28) -> 7 | G28: =SUMIFS(Histórico!$F$5:$F$5000,Histórico!$D$5:$D$5000,$B28,Histórico!$A$5:$A$5000,">="&DESDE,Histórico!$A$5:$A$5000,"<="&HASTA) -> 147.18 | H28: =SUMIFS(Histórico!$L$5:$L$5000,Histórico!$D$5:$D$5000,$B28,Histórico!$A$5:$A$5000,">="&DESDE,Histórico!$A$5:$A$5000,"<="&HASTA) -> 19 | I28: =H28*RATIO -> 19.904762 | J28: =IF(I28>0,G28/I28,"") -> 7.3942105 | K28: =I28*BEN_PEDIDO-G28*(1+RECARGO) -> 86.9 | L28: =IFERROR(SUMIFS(Histórico!$M$5:$M$5000,Histórico!$D$5:$D$5000,$B28,Histórico!$A$5:$A$5000,">="&DESDE,Histórico!$A$5:$A$5000,"<="&HASTA)/SUMIFS(Histórico!$G$5:$G$5000,Histórico!$D$5:$D$5000,$B28,Histórico!$A$5:$A$5000,">="&DESDE,Histórico!$A$5:$A$5000,"<="&HASTA),"") -> 0.12794478 | M28: =IFERROR(SUMIFS(Histórico!$H$5:$H$5000,Histórico!$D$5:$D$5000,$B28,Histórico!$A$5:$A$5000,">="&DESDE,Histórico!$A$5:$A$5000,"<="&HASTA)/SUMIFS(Histórico!$G$5:$G$5000,Histórico!$D$5:$D$5000,$B28,Histórico!$A$5:$A$5000,">="&DESDE,Histórico!$A$5:$A$5000,"<="&HASTA),"") -> 0.01785625
B30: POR CUERPO (guion después del hook)
B31: Cuerpo | F31: Anuncios | G31: Gasto | H31: Compras Meta | I31: Pedidos est. | J31: CPA real | K31: Beneficio est. | L31: Gancho | M31: CTR
B32: C1 · Rabia · el bote habla | F32: =COUNTIF(Creativos!$E$5:$E$16,LEFT($B32,FIND(" · ",$B32&" · ")-1)) -> 2 | G32: =SUMIFS(Histórico!$F$5:$F$5000,Histórico!$R$5:$R$5000,LEFT($B32,FIND(" · ",$B32&" · ")-1),Histórico!$A$5:$A$5000,">="&DESDE,Histórico!$A$5:$A$5000,"<="&HASTA) -> 13.67 | H32: =SUMIFS(Histórico!$L$5:$L$5000,Histórico!$R$5:$R$5000,LEFT($B32,FIND(" · ",$B32&" · ")-1),Histórico!$A$5:$A$5000,">="&DESDE,Histórico!$A$5:$A$5000,"<="&HASTA) -> 2 | I32: =H32*RATIO -> 2.0952381 | J32: =IF(I32>0,G32/I32,"") -> 6.5243182 | K32: =I32*BEN_PEDIDO-G32*(1+RECARGO) -> 10.97 | L32: =IFERROR(SUMIFS(Histórico!$M$5:$M$5000,Histórico!$R$5:$R$5000,LEFT($B32,FIND(" · ",$B32&" · ")-1),Histórico!$A$5:$A$5000,">="&DESDE,Histórico!$A$5:$A$5000,"<="&HASTA)/SUMIFS(Histórico!$G$5:$G$5000,Histórico!$R$5:$R$5000,LEFT($B32,FIND(" · ",$B32&" · ")-1),Histórico!$A$5:$A$5000,">="&DESDE,Histórico!$A$5:$A$5000,"<="&HASTA),"") -> 0.25369458 | M32: =IFERROR(SUMIFS(Histórico!$H$5:$H$5000,Histórico!$R$5:$R$5000,LEFT($B32,FIND(" · ",$B32&" · ")-1),Histórico!$A$5:$A$5000,">="&DESDE,Histórico!$A$5:$A$5000,"<="&HASTA)/SUMIFS(Histórico!$G$5:$G$5000,Histórico!$R$5:$R$5000,LEFT($B32,FIND(" · ",$B32&" · ")-1),Histórico!$A$5:$A$5000,">="&DESDE,Histórico!$A$5:$A$5000,"<="&HASTA),"") -> 0.02545156
B33: C2 · Dinero · vender el coche | F33: =COUNTIF(Creativos!$E$5:$E$16,LEFT($B33,FIND(" · ",$B33&" · ")-1)) -> 3 | G33: =SUMIFS(Histórico!$F$5:$F$5000,Histórico!$R$5:$R$5000,LEFT($B33,FIND(" · ",$B33&" · ")-1),Histórico!$A$5:$A$5000,">="&DESDE,Histórico!$A$5:$A$5000,"<="&HASTA) -> 14.36 | H33: =SUMIFS(Histórico!$L$5:$L$5000,Histórico!$R$5:$R$5000,LEFT($B33,FIND(" · ",$B33&" · ")-1),Histórico!$A$5:$A$5000,">="&DESDE,Histórico!$A$5:$A$5000,"<="&HASTA) -> 0 | I33: =H33*RATIO -> 0 | J33: =IF(I33>0,G33/I33,"") | K33: =I33*BEN_PEDIDO-G33*(1+RECARGO) -> -14.36 | L33: =IFERROR(SUMIFS(Histórico!$M$5:$M$5000,Histórico!$R$5:$R$5000,LEFT($B33,FIND(" · ",$B33&" · ")-1),Histórico!$A$5:$A$5000,">="&DESDE,Histórico!$A$5:$A$5000,"<="&HASTA)/SUMIFS(Histórico!$G$5:$G$5000,Histórico!$R$5:$R$5000,LEFT($B33,FIND(" · ",$B33&" · ")-1),Histórico!$A$5:$A$5000,">="&DESDE,Histórico!$A$5:$A$5000,"<="&HASTA),"") -> 0.19277108 | M33: =IFERROR(SUMIFS(Histórico!$H$5:$H$5000,Histórico!$R$5:$R$5000,LEFT($B33,FIND(" · ",$B33&" · ")-1),Histórico!$A$5:$A$5000,">="&DESDE,Histórico!$A$5:$A$5000,"<="&HASTA)/SUMIFS(Histórico!$G$5:$G$5000,Histórico!$R$5:$R$5000,LEFT($B33,FIND(" · ",$B33&" · ")-1),Histórico!$A$5:$A$5000,">="&DESDE,Histórico!$A$5:$A$5000,"<="&HASTA),"") -> 0.031510658
B34: C3 · Demostración real · sin cortes | F34: =COUNTIF(Creativos!$E$5:$E$16,LEFT($B34,FIND(" · ",$B34&" · ")-1)) -> 7 | G34: =SUMIFS(Histórico!$F$5:$F$5000,Histórico!$R$5:$R$5000,LEFT($B34,FIND(" · ",$B34&" · ")-1),Histórico!$A$5:$A$5000,">="&DESDE,Histórico!$A$5:$A$5000,"<="&HASTA) -> 147.18 | H34: =SUMIFS(Histórico!$L$5:$L$5000,Histórico!$R$5:$R$5000,LEFT($B34,FIND(" · ",$B34&" · ")-1),Histórico!$A$5:$A$5000,">="&DESDE,Histórico!$A$5:$A$5000,"<="&HASTA) -> 19 | I34: =H34*RATIO -> 19.904762 | J34: =IF(I34>0,G34/I34,"") -> 7.3942105 | K34: =I34*BEN_PEDIDO-G34*(1+RECARGO) -> 86.9 | L34: =IFERROR(SUMIFS(Histórico!$M$5:$M$5000,Histórico!$R$5:$R$5000,LEFT($B34,FIND(" · ",$B34&" · ")-1),Histórico!$A$5:$A$5000,">="&DESDE,Histórico!$A$5:$A$5000,"<="&HASTA)/SUMIFS(Histórico!$G$5:$G$5000,Histórico!$R$5:$R$5000,LEFT($B34,FIND(" · ",$B34&" · ")-1),Histórico!$A$5:$A$5000,">="&DESDE,Histórico!$A$5:$A$5000,"<="&HASTA),"") -> 0.12794478 | M34: =IFERROR(SUMIFS(Histórico!$H$5:$H$5000,Histórico!$R$5:$R$5000,LEFT($B34,FIND(" · ",$B34&" · ")-1),Histórico!$A$5:$A$5000,">="&DESDE,Histórico!$A$5:$A$5000,"<="&HASTA)/SUMIFS(Histórico!$G$5:$G$5000,Histórico!$R$5:$R$5000,LEFT($B34,FIND(" · ",$B34&" · ")-1),Histórico!$A$5:$A$5000,">="&DESDE,Histórico!$A$5:$A$5000,"<="&HASTA),"") -> 0.01785625
B36: POR CONCEPTO DE HOOK
B37: Concepto del hook | F37: Anuncios | G37: Gasto | H37: Compras Meta | I37: Pedidos est. | J37: CPA real | K37: Beneficio est. | L37: Gancho | M37: CTR
B38: Rayón en el parking | F38: =COUNTIF(Creativos!$H$5:$H$16,$B38) -> 2 | G38: =SUMIFS(Histórico!$F$5:$F$5000,Histórico!$S$5:$S$5000,$B38,Histórico!$A$5:$A$5000,">="&DESDE,Histórico!$A$5:$A$5000,"<="&HASTA) -> 13.67 | H38: =SUMIFS(Histórico!$L$5:$L$5000,Histórico!$S$5:$S$5000,$B38,Histórico!$A$5:$A$5000,">="&DESDE,Histórico!$A$5:$A$5000,"<="&HASTA) -> 2 | I38: =H38*RATIO -> 2.0952381 | J38: =IF(I38>0,G38/I38,"") -> 6.5243182 | K38: =I38*BEN_PEDIDO-G38*(1+RECARGO) -> 10.97 | L38: =IFERROR(SUMIFS(Histórico!$M$5:$M$5000,Histórico!$S$5:$S$5000,$B38,Histórico!$A$5:$A$5000,">="&DESDE,Histórico!$A$5:$A$5000,"<="&HASTA)/SUMIFS(Histórico!$G$5:$G$5000,Histórico!$S$5:$S$5000,$B38,Histórico!$A$5:$A$5000,">="&DESDE,Histórico!$A$5:$A$5000,"<="&HASTA),"") -> 0.25369458 | M38: =IFERROR(SUMIFS(Histórico!$H$5:$H$5000,Histórico!$S$5:$S$5000,$B38,Histórico!$A$5:$A$5000,">="&DESDE,Histórico!$A$5:$A$5000,"<="&HASTA)/SUMIFS(Histórico!$G$5:$G$5000,Histórico!$S$5:$S$5000,$B38,Histórico!$A$5:$A$5000,">="&DESDE,Histórico!$A$5:$A$5000,"<="&HASTA),"") -> 0.02545156
B39: Vender el coche | F39: =COUNTIF(Creativos!$H$5:$H$16,$B39) -> 3 | G39: =SUMIFS(Histórico!$F$5:$F$5000,Histórico!$S$5:$S$5000,$B39,Histórico!$A$5:$A$5000,">="&DESDE,Histórico!$A$5:$A$5000,"<="&HASTA) -> 14.36 | H39: =SUMIFS(Histórico!$L$5:$L$5000,Histórico!$S$5:$S$5000,$B39,Histórico!$A$5:$A$5000,">="&DESDE,Histórico!$A$5:$A$5000,"<="&HASTA) -> 0 | I39: =H39*RATIO -> 0 | J39: =IF(I39>0,G39/I39,"") | K39: =I39*BEN_PEDIDO-G39*(1+RECARGO) -> -14.36 | L39: =IFERROR(SUMIFS(Histórico!$M$5:$M$5000,Histórico!$S$5:$S$5000,$B39,Histórico!$A$5:$A$5000,">="&DESDE,Histórico!$A$5:$A$5000,"<="&HASTA)/SUMIFS(Histórico!$G$5:$G$5000,Histórico!$S$5:$S$5000,$B39,Histórico!$A$5:$A$5000,">="&DESDE,Histórico!$A$5:$A$5000,"<="&HASTA),"") -> 0.19277108 | M39: =IFERROR(SUMIFS(Histórico!$H$5:$H$5000,Histórico!$S$5:$S$5000,$B39,Histórico!$A$5:$A$5000,">="&DESDE,Histórico!$A$5:$A$5000,"<="&HASTA)/SUMIFS(Histórico!$G$5:$G$5000,Histórico!$S$5:$S$5000,$B39,Histórico!$A$5:$A$5000,">="&DESDE,Histórico!$A$5:$A$5000,"<="&HASTA),"") -> 0.031510658
B40: Bolardo | F40: =COUNTIF(Creativos!$H$5:$H$16,$B40) -> 1 | G40: =SUMIFS(Histórico!$F$5:$F$5000,Histórico!$S$5:$S$5000,$B40,Histórico!$A$5:$A$5000,">="&DESDE,Histórico!$A$5:$A$5000,"<="&HASTA) -> 85.54 | H40: =SUMIFS(Histórico!$L$5:$L$5000,Histórico!$S$5:$S$5000,$B40,Histórico!$A$5:$A$5000,">="&DESDE,Histórico!$A$5:$A$5000,"<="&HASTA) -> 10 | I40: =H40*RATIO -> 10.47619 | J40: =IF(I40>0,G40/I40,"") -> 8.1651818 | K40: =I40*BEN_PEDIDO-G40*(1+RECARGO) -> 37.66 | L40: =IFERROR(SUMIFS(Histórico!$M$5:$M$5000,Histórico!$S$5:$S$5000,$B40,Histórico!$A$5:$A$5000,">="&DESDE,Histórico!$A$5:$A$5000,"<="&HASTA)/SUMIFS(Histórico!$G$5:$G$5000,Histórico!$S$5:$S$5000,$B40,Histórico!$A$5:$A$5000,">="&DESDE,Histórico!$A$5:$A$5000,"<="&HASTA),"") -> 0.12108162 | M40: =IFERROR(SUMIFS(Histórico!$H$5:$H$5000,Histórico!$S$5:$S$5000,$B40,Histórico!$A$5:$A$5000,">="&DESDE,Histórico!$A$5:$A$5000,"<="&HASTA)/SUMIFS(Histórico!$G$5:$G$5000,Histórico!$S$5:$S$5000,$B40,Histórico!$A$5:$A$5000,">="&DESDE,Histórico!$A$5:$A$5000,"<="&HASTA),"") -> 0.016097148
B41: Llaves | F41: =COUNTIF(Creativos!$H$5:$H$16,$B41) -> 2 | G41: =SUMIFS(Histórico!$F$5:$F$5000,Histórico!$S$5:$S$5000,$B41,Histórico!$A$5:$A$5000,">="&DESDE,Histórico!$A$5:$A$5000,"<="&HASTA) -> 39.51 | H41: =SUMIFS(Histórico!$L$5:$L$5000,Histórico!$S$5:$S$5000,$B41,Histórico!$A$5:$A$5000,">="&DESDE,Histórico!$A$5:$A$5000,"<="&HASTA) -> 6 | I41: =H41*RATIO -> 6.2857143 | J41: =IF(I41>0,G41/I41,"") -> 6.2856818 | K41: =I41*BEN_PEDIDO-G41*(1+RECARGO) -> 34.41 | L41: =IFERROR(SUMIFS(Histórico!$M$5:$M$5000,Histórico!$S$5:$S$5000,$B41,Histórico!$A$5:$A$5000,">="&DESDE,Histórico!$A$5:$A$5000,"<="&HASTA)/SUMIFS(Histórico!$G$5:$G$5000,Histórico!$S$5:$S$5000,$B41,Histórico!$A$5:$A$5000,">="&DESDE,Histórico!$A$5:$A$5000,"<="&HASTA),"") -> 0.11111111 | M41: =IFERROR(SUMIFS(Histórico!$H$5:$H$5000,Histórico!$S$5:$S$5000,$B41,Histórico!$A$5:$A$5000,">="&DESDE,Histórico!$A$5:$A$5000,"<="&HASTA)/SUMIFS(Histórico!$G$5:$G$5000,Histórico!$S$5:$S$5000,$B41,Histórico!$A$5:$A$5000,">="&DESDE,Histórico!$A$5:$A$5000,"<="&HASTA),"") -> 0.018558689
B42: Perro | F42: =COUNTIF(Creativos!$H$5:$H$16,$B42) -> 2 | G42: =SUMIFS(Histórico!$F$5:$F$5000,Histórico!$S$5:$S$5000,$B42,Histórico!$A$5:$A$5000,">="&DESDE,Histórico!$A$5:$A$5000,"<="&HASTA) -> 8.5 | H42: =SUMIFS(Histórico!$L$5:$L$5000,Histórico!$S$5:$S$5000,$B42,Histórico!$A$5:$A$5000,">="&DESDE,Histórico!$A$5:$A$5000,"<="&HASTA) -> 2 | I42: =H42*RATIO -> 2.0952381 | J42: =IF(I42>0,G42/I42,"") -> 4.0568182 | K42: =I42*BEN_PEDIDO-G42*(1+RECARGO) -> 16.14 | L42: =IFERROR(SUMIFS(Histórico!$M$5:$M$5000,Histórico!$S$5:$S$5000,$B42,Histórico!$A$5:$A$5000,">="&DESDE,Histórico!$A$5:$A$5000,"<="&HASTA)/SUMIFS(Histórico!$G$5:$G$5000,Histórico!$S$5:$S$5000,$B42,Histórico!$A$5:$A$5000,">="&DESDE,Histórico!$A$5:$A$5000,"<="&HASTA),"") -> 0.18252934 | M42: =IFERROR(SUMIFS(Histórico!$H$5:$H$5000,Histórico!$S$5:$S$5000,$B42,Histórico!$A$5:$A$5000,">="&DESDE,Histórico!$A$5:$A$5000,"<="&HASTA)/SUMIFS(Histórico!$G$5:$G$5000,Histórico!$S$5:$S$5000,$B42,Histórico!$A$5:$A$5000,">="&DESDE,Histórico!$A$5:$A$5000,"<="&HASTA),"") -> 0.024771838
B43: Carrito | F43: =COUNTIF(Creativos!$H$5:$H$16,$B43) -> 2 | G43: =SUMIFS(Histórico!$F$5:$F$5000,Histórico!$S$5:$S$5000,$B43,Histórico!$A$5:$A$5000,">="&DESDE,Histórico!$A$5:$A$5000,"<="&HASTA) -> 13.63 | H43: =SUMIFS(Histórico!$L$5:$L$5000,Histórico!$S$5:$S$5000,$B43,Histórico!$A$5:$A$5000,">="&DESDE,Histórico!$A$5:$A$5000,"<="&HASTA) -> 1 | I43: =H43*RATIO -> 1.047619 | J43: =IF(I43>0,G43/I43,"") -> 13.010455 | K43: =I43*BEN_PEDIDO-G43*(1+RECARGO) -> -1.31 | L43: =IFERROR(SUMIFS(Histórico!$M$5:$M$5000,Histórico!$S$5:$S$5000,$B43,Histórico!$A$5:$A$5000,">="&DESDE,Histórico!$A$5:$A$5000,"<="&HASTA)/SUMIFS(Histórico!$G$5:$G$5000,Histórico!$S$5:$S$5000,$B43,Histórico!$A$5:$A$5000,">="&DESDE,Histórico!$A$5:$A$5000,"<="&HASTA),"") -> 0.26506024 | M43: =IFERROR(SUMIFS(Histórico!$H$5:$H$5000,Histórico!$S$5:$S$5000,$B43,Histórico!$A$5:$A$5000,">="&DESDE,Histórico!$A$5:$A$5000,"<="&HASTA)/SUMIFS(Histórico!$G$5:$G$5000,Histórico!$S$5:$S$5000,$B43,Histórico!$A$5:$A$5000,">="&DESDE,Histórico!$A$5:$A$5000,"<="&HASTA),"") -> 0.036144578

Sheet Mapa
B1: Mapa de creativos: ángulo → cuerpo → hooks
B2: Tu pizarra de estructura con los números al lado. Se rellena sola desde Creativos y Cuerpos (periodo del Panel).
B4: AS1 · RABIA — no fue culpa mía · Cuerpo C1: Rabia · el bote habla
B5: CUERPO (lo mismo para todos sus hooks) | C5: ANUNCIO | D5: HOOK | E5: Gasto | F5: Compras | G5: CPA real | H5: Beneficio est. | I5: Veredicto
B6: =IFERROR(INDEX(Cuerpos!$K$5:$K$17,MATCH("C1",Cuerpos!$A$5:$A$17,0)),"") -> No la hiciste tú, pero la vas a pagar tú. Vas al taller, te piden 120 euros y te quedas dos días sin coche, por una raya que no es culpa tuya. Oye, ¿y si no hiciera falta? Me pulverizas, pasas el paño y la raya deja de verse. No lijo, relleno. Tu coche tiene el barniz que tiene. Yo no te quito ni una capa. 29 euros. Y me pagas cuando llego a tu casa. Haz clic en el enlace. Guárdame en el maletero y olvídate. | C6: =Creativos!B5 -> PIXARSUPER_H1 | D6: =IF(Creativos!I5="","[visual] "&Creativos!H5,Creativos!I5) -> Vuelves al coche y ahí está, un rayón nuevo y ni una nota. | E6: =Creativos!M5 -> 10.3 | F6: =Creativos!Q5 -> 2 | G6: =Creativos!S5 -> 4.9159091 | H6: =Creativos!T5 -> 14.34 | I6: =Creativos!AA5 -> PROMETEDOR
C7: =Creativos!B6 -> PIXARSUPER_H2 | D7: =IF(Creativos!I6="","[visual] "&Creativos!H6,Creativos!I6) -> ¡Sorpresa! Un nuevo rayón y ni una nota en el parabrisas. | E7: =Creativos!M6 -> 3.37 | F7: =Creativos!Q6 -> 0 | G7: =Creativos!S6 | H7: =Creativos!T6 -> -3.37 | I7: =Creativos!AA6 -> APRENDIENDO
C8: Total | E8: =SUM(E6:E7) -> 13.67 | F8: =SUM(F6:F7) -> 2 | G8: =IF(F8*RATIO>0,E8/(F8*RATIO),"") -> 6.5243182 | H8: =SUM(H6:H7) -> 10.97
B10: AS2 · DINERO — voy a vender el coche · Cuerpo C2: Dinero · vender el coche
B11: CUERPO (lo mismo para todos sus hooks) | C11: ANUNCIO | D11: HOOK | E11: Gasto | F11: Compras | G11: CPA real | H11: Beneficio est. | I11: Veredicto
B12: =IFERROR(INDEX(Cuerpos!$K$5:$K$17,MATCH("C2",Cuerpos!$A$5:$A$17,0)),"") -> Un dineral en el taller. La pulidora te come barniz y el del súper no hace nada. Pues no hace falta. Soy Ceralux y funciono al revés que una pulidora. Ella lija el barniz hasta igualar la raya. Yo la relleno y te dejo el barniz intacto. Pasa la uña por encima del rayón. Si se engancha, es demasiado profunda y yo no te sirvo. Si no se engancha, soy tu solución. Puesto menos de 30 euros y no pagas nada hasta tenerme en la mano. 10 minutos y ahora te quedas tranquilo de haberlo vendido por lo que vale. | C12: =Creativos!B7 -> PIXARVENTA_H1 | D12: =IF(Creativos!I7="","[visual] "&Creativos!H7,Creativos!I7) -> Vas a vender tu coche esta semana y esos rayones van a decidir lo que te ofrecen. No merece la pena, ¿no? | E12: =Creativos!M7 -> 9.17 | F12: =Creativos!Q7 -> 0 | G12: =Creativos!S7 | H12: =Creativos!T7 -> -9.17 | I12: =Creativos!AA7 -> VIGILAR
C13: =Creativos!B8 -> PIXARVENTA_H2 | D13: =IF(Creativos!I8="","[visual] "&Creativos!H8,Creativos!I8) -> Vas a vender el coche y esos cuatro rayones le van a dar la excusa perfecta para bajarte el precio. | E13: =Creativos!M8 -> 2.35 | F13: =Creativos!Q8 -> 0 | G13: =Creativos!S8 | H13: =Creativos!T8 -> -2.35 | I13: =Creativos!AA8 -> APRENDIENDO
C14: =Creativos!B9 -> PIXARVENTA_H3 | D14: =IF(Creativos!I9="","[visual] "&Creativos!H9,Creativos!I9) -> Siempre has mimado tu coche y ahora que lo vendes, te van a regatear por cuatro rayones que ni son tuyos. | E14: =Creativos!M9 -> 2.84 | F14: =Creativos!Q9 -> 0 | G14: =Creativos!S9 | H14: =Creativos!T9 -> -2.84 | I14: =Creativos!AA9 -> APRENDIENDO
C15: Total | E15: =SUM(E12:E14) -> 14.36 | F15: =SUM(F12:F14) -> 0 | G15: =IF(F15*RATIO>0,E15/(F15*RATIO),"") | H15: =SUM(H12:H14) -> -14.36
B17: AS3 · BROAD — hooks visuales · Cuerpo C3: Demostración real · sin cortes
B18: CUERPO (lo mismo para todos sus hooks) | C18: ANUNCIO | D18: HOOK | E18: Gasto | F18: Compras | G18: CPA real | H18: Beneficio est. | I18: Veredicto
B19: =IFERROR(INDEX(Cuerpos!$K$5:$K$17,MATCH("C3",Cuerpos!$A$5:$A$17,0)),"") -> Este es el reparador de arañazos del que habla todo el mundo. Míralo, sin cortes y sin Photoshop. Dos pulsaciones sobre el paño y lo pasamos directamente por encima del arañazo. La fórmula de nanopolímeros rellena la marca y te alisa la superficie al instante, sin lijar el barniz. Esa raya blanca, un par de pasadas y deja de verse. Funciona en cualquier color de coche, mismo resultado. No pagas nada hasta que lo tienes en la mano y lo ves funcionar. Hoy te llevas dos botes por 39,90 y el envío te sale gratis. Pagas en casa cuando te llegue. El enlace está aquí abajo. | C19: =Creativos!B10 -> BROAD_H1 BOLARDO | D19: =IF(Creativos!I10="","[visual] "&Creativos!H10,Creativos!I10) -> [visual] Bolardo | E19: =Creativos!M10 -> 85.54 | F19: =Creativos!Q10 -> 10 | G19: =Creativos!S10 -> 8.1651818 | H19: =Creativos!T10 -> 37.66 | I19: =Creativos!AA10 -> ESCALAR
C20: =Creativos!B11 -> BROAD_H2 LLAVES | D20: =IF(Creativos!I11="","[visual] "&Creativos!H11,Creativos!I11) -> [visual] Llaves | E20: =Creativos!M11 -> 37.7 | F20: =Creativos!Q11 -> 6 | G20: =Creativos!S11 -> 5.9977273 | H20: =Creativos!T11 -> 36.22 | I20: =Creativos!AA11 -> ESCALAR
C21: =Creativos!B12 -> BROAD_H3 LLAVES | D21: =IF(Creativos!I12="","[visual] "&Creativos!H12,Creativos!I12) -> [visual] Llaves | E21: =Creativos!M12 -> 1.81 | F21: =Creativos!Q12 -> 0 | G21: =Creativos!S12 | H21: =Creativos!T12 -> -1.81 | I21: =Creativos!AA12 -> APRENDIENDO
C22: =Creativos!B13 -> BROAD_H4 PERRO | D22: =IF(Creativos!I13="","[visual] "&Creativos!H13,Creativos!I13) -> [visual] Perro | E22: =Creativos!M13 -> 8.45 | F22: =Creativos!Q13 -> 2 | G22: =Creativos!S13 -> 4.0329545 | H22: =Creativos!T13 -> 16.19 | I22: =Creativos!AA13 -> PROMETEDOR
C23: =Creativos!B14 -> BROAD_H5 PERRO | D23: =IF(Creativos!I14="","[visual] "&Creativos!H14,Creativos!I14) -> [visual] Perro | E23: =Creativos!M14 -> 0.05 | F23: =Creativos!Q14 -> 0 | G23: =Creativos!S14 | H23: =Creativos!T14 -> -0.05 | I23: =Creativos!AA14 -> APRENDIENDO
C24: =Creativos!B15 -> BROAD_H6 CARRITO | D24: =IF(Creativos!I15="","[visual] "&Creativos!H15,Creativos!I15) -> [visual] Carrito | E24: =Creativos!M15 -> 0.73 | F24: =Creativos!Q15 -> 0 | G24: =Creativos!S15 | H24: =Creativos!T15 -> -0.73 | I24: =Creativos!AA15 -> APRENDIENDO
C25: =Creativos!B16 -> BROAD_H7 CARRITO | D25: =IF(Creativos!I16="","[visual] "&Creativos!H16,Creativos!I16) -> [visual] Carrito | E25: =Creativos!M16 -> 12.9 | F25: =Creativos!Q16 -> 1 | G25: =Creativos!S16 -> 12.313636 | H25: =Creativos!T16 -> -0.58 | I25: =Creativos!AA16 -> VIGILAR
C26: Total | E26: =SUM(E19:E25) -> 147.18 | F26: =SUM(F19:F25) -> 19 | G26: =IF(F26*RATIO>0,E26/(F26*RATIO),"") -> 7.3942105 | H26: =SUM(H19:H25) -> 86.9

Sheet Creativos
B1: Creativos: estructura y rendimiento
B2: Una fila por anuncio. Lo amarillo lo editas tú (hook, concepto, cuerpo, notas). Las métricas son del periodo elegido en el Panel.
A4: ID anuncio | B4: Anuncio | C4: Campaña | D4: Ángulo (conjunto) | E4: Cuerpo | F4: Formato | G4: Tipo de hook | H4: Concepto del hook | I4: Hook (texto, o qué se ve en los 3 primeros segundos) | J4: Alta | K4: Estado | L4: Notas / aprendizaje | M4: Gasto | N4: Impresiones | O4: Clics | P4: Visitas web | Q4: Compras Meta | R4: Pedidos reales est. | S4: CPA real | T4: Beneficio est. | U4: Gancho (ven el 25%) | V4: Retención (25%→50%) | W4: CTR | X4: Llega a la web | Y4: Compra / clic | Z4: Tiempo medio (s) | AA4: Veredicto | AB4: Diagnóstico | AC4: orden
A5: 120254996455720271 | B5: PIXARSUPER_H1 | C5: CeraLux ES — Test 3 ángulos — Oct 2026 | D5: AS1 · RABIA — no fue culpa mía | E5: C1 | F5: Animación estilo Pixar (habla el bote) | G5: Texto | H5: Rayón en el parking | I5: Vuelves al coche y ahí está, un rayón nuevo y ni una nota. | J5: 46300 | K5: Activo | M5: =SUMIFS(Histórico!$F$5:$F$5000,Histórico!$B$5:$B$5000,$A5,Histórico!$A$5:$A$5000,">="&DESDE,Histórico!$A$5:$A$5000,"<="&HASTA) -> 10.3 | N5: =SUMIFS(Histórico!$G$5:$G$5000,Histórico!$B$5:$B$5000,$A5,Histórico!$A$5:$A$5000,">="&DESDE,Histórico!$A$5:$A$5000,"<="&HASTA) -> 920 | O5: =SUMIFS(Histórico!$H$5:$H$5000,Histórico!$B$5:$B$5000,$A5,Histórico!$A$5:$A$5000,">="&DESDE,Histórico!$A$5:$A$5000,"<="&HASTA) -> 26 | P5: =SUMIFS(Histórico!$I$5:$I$5000,Histórico!$B$5:$B$5000,$A5,Histórico!$A$5:$A$5000,">="&DESDE,Histórico!$A$5:$A$5000,"<="&HASTA) -> 10 | Q5: =SUMIFS(Histórico!$L$5:$L$5000,Histórico!$B$5:$B$5000,$A5,Histórico!$A$5:$A$5000,">="&DESDE,Histórico!$A$5:$A$5000,"<="&HASTA) -> 2 | R5: =Q5*RATIO -> 2.0952381 | S5: =IF(R5>0,M5/R5,"") -> 4.9159091 | T5: =R5*BEN_PEDIDO-M5*(1+RECARGO) -> 14.34 | U5: =IF(N5>0,SUMIFS(Histórico!$M$5:$M$5000,Histórico!$B$5:$B$5000,$A5,Histórico!$A$5:$A$5000,">="&DESDE,Histórico!$A$5:$A$5000,"<="&HASTA)/N5,"") -> 0.2673913 | V5: =IF(SUMIFS(Histórico!$M$5:$M$5000,Histórico!$B$5:$B$5000,$A5,Histórico!$A$5:$A$5000,">="&DESDE,Histórico!$A$5:$A$5000,"<="&HASTA)>0,SUMIFS(Histórico!$N$5:$N$5000,Histórico!$B$5:$B$5000,$A5,Histórico!$A$5:$A$5000,">="&DESDE,Histórico!$A$5:$A$5000,"<="&HASTA)/SUMIFS(Histórico!$M$5:$M$5000,Histórico!$B$5:$B$5000,$A5,Histórico!$A$5:$A$5000,">="&DESDE,Histórico!$A$5:$A$5000,"<="&HASTA),"") -> 0.69918699 | W5: =IF(N5>0,O5/N5,"") -> 0.02826087 | X5: =IF(O5>0,P5/O5,"") -> 0.38461538 | Y5: =IF(O5>0,Q5/O5,"") -> 0.076923077 | Z5: =IF(N5>0,SUMIFS(Histórico!$T$5:$T$5000,Histórico!$B$5:$B$5000,$A5,Histórico!$A$5:$A$5000,">="&DESDE,Histórico!$A$5:$A$5000,"<="&HASTA)/N5,"") -> 7.4434783 | AA5: =IF(M5=0,"SIN GASTO",IF(Q5=0,IF(M5>=APG_SV*CPA_BE,"APAGAR",IF(M5>=0.5*CPA_BE,"VIGILAR","APRENDIENDO")),IF(AND(S5<=UMB_ESC*CPA_BE,Q5>=3),"ESCALAR",IF(AND(S5<=CPA_BE,Q5>=3),"MANTENER",IF(S5<=CPA_BE,"PROMETEDOR",IF(M5>=APG_CV*CPA_BE,"APAGAR","VIGILAR")))))) -> PROMETEDOR | AB5: =IF(N5<MIN_IMPR,"Pocos datos todavía",IF(AND(ISNUMBER(U5),U5<0.7*MEDIA_GANCHO),"Gancho flojo: cambia los 3 primeros segundos",IF(AND(ISNUMBER(W5),W5<0.7*MEDIA_CTR),"Enganchan pero no hacen clic: refuerza oferta y llamada a la acción",IF(AND(O5>=20,ISNUMBER(Y5),Y5<0.6*MEDIA_CVR),"Hacen clic pero no compran: revisa ángulo y página",IF(AND(ISNUMBER(U5),U5>=1.3*MEDIA_GANCHO),"Gancho por encima de la media: reutiliza este inicio","En la media de la campaña"))))) -> Gancho por encima de la media: reutiliza este inicio | AC5: =IF(M5>0,T5+ROW()/1000000,-1000000+ROW()) -> 14.340005
A6: 120254996456760271 | B6: PIXARSUPER_H2 | C6: CeraLux ES — Test 3 ángulos — Oct 2026 | D6: AS1 · RABIA — no fue culpa mía | E6: C1 | F6: Animación estilo Pixar (habla el bote) | G6: Texto | H6: Rayón en el parking | I6: ¡Sorpresa! Un nuevo rayón y ni una nota en el parabrisas. | J6: 46300 | K6: Activo | M6: =SUMIFS(Histórico!$F$5:$F$5000,Histórico!$B$5:$B$5000,$A6,Histórico!$A$5:$A$5000,">="&DESDE,Histórico!$A$5:$A$5000,"<="&HASTA) -> 3.37 | N6: =SUMIFS(Histórico!$G$5:$G$5000,Histórico!$B$5:$B$5000,$A6,Histórico!$A$5:$A$5000,">="&DESDE,Histórico!$A$5:$A$5000,"<="&HASTA) -> 298 | O6: =SUMIFS(Histórico!$H$5:$H$5000,Histórico!$B$5:$B$5000,$A6,Histórico!$A$5:$A$5000,">="&DESDE,Histórico!$A$5:$A$5000,"<="&HASTA) -> 5 | P6: =SUMIFS(Histórico!$I$5:$I$5000,Histórico!$B$5:$B$5000,$A6,Histórico!$A$5:$A$5000,">="&DESDE,Histórico!$A$5:$A$5000,"<="&HASTA) -> 0 | Q6: =SUMIFS(Histórico!$L$5:$L$5000,Histórico!$B$5:$B$5000,$A6,Histórico!$A$5:$A$5000,">="&DESDE,Histórico!$A$5:$A$5000,"<="&HASTA) -> 0 | R6: =Q6*RATIO -> 0 | S6: =IF(R6>0,M6/R6,"") | T6: =R6*BEN_PEDIDO-M6*(1+RECARGO) -> -3.37 | U6: =IF(N6>0,SUMIFS(Histórico!$M$5:$M$5000,Histórico!$B$5:$B$5000,$A6,Histórico!$A$5:$A$5000,">="&DESDE,Histórico!$A$5:$A$5000,"<="&HASTA)/N6,"") -> 0.2114094 | V6: =IF(SUMIFS(Histórico!$M$5:$M$5000,Histórico!$B$5:$B$5000,$A6,Histórico!$A$5:$A$5000,">="&DESDE,Histórico!$A$5:$A$5000,"<="&HASTA)>0,SUMIFS(Histórico!$N$5:$N$5000,Histórico!$B$5:$B$5000,$A6,Histórico!$A$5:$A$5000,">="&DESDE,Histórico!$A$5:$A$5000,"<="&HASTA)/SUMIFS(Histórico!$M$5:$M$5000,Histórico!$B$5:$B$5000,$A6,Histórico!$A$5:$A$5000,">="&DESDE,Histórico!$A$5:$A$5000,"<="&HASTA),"") -> 0.74603175 | W6: =IF(N6>0,O6/N6,"") -> 0.016778523 | X6: =IF(O6>0,P6/O6,"") -> 0 | Y6: =IF(O6>0,Q6/O6,"") -> 0 | Z6: =IF(N6>0,SUMIFS(Histórico!$T$5:$T$5000,Histórico!$B$5:$B$5000,$A6,Histórico!$A$5:$A$5000,">="&DESDE,Histórico!$A$5:$A$5000,"<="&HASTA)/N6,"") -> 7.7248322 | AA6: =IF(M6=0,"SIN GASTO",IF(Q6=0,IF(M6>=APG_SV*CPA_BE,"APAGAR",IF(M6>=0.5*CPA_BE,"VIGILAR","APRENDIENDO")),IF(AND(S6<=UMB_ESC*CPA_BE,Q6>=3),"ESCALAR",IF(AND(S6<=CPA_BE,Q6>=3),"MANTENER",IF(S6<=CPA_BE,"PROMETEDOR",IF(M6>=APG_CV*CPA_BE,"APAGAR","VIGILAR")))))) -> APRENDIENDO | AB6: =IF(N6<MIN_IMPR,"Pocos datos todavía",IF(AND(ISNUMBER(U6),U6<0.7*MEDIA_GANCHO),"Gancho flojo: cambia los 3 primeros segundos",IF(AND(ISNUMBER(W6),W6<0.7*MEDIA_CTR),"Enganchan pero no hacen clic: refuerza oferta y llamada a la acción",IF(AND(O6>=20,ISNUMBER(Y6),Y6<0.6*MEDIA_CVR),"Hacen clic pero no compran: revisa ángulo y página",IF(AND(ISNUMBER(U6),U6>=1.3*MEDIA_GANCHO),"Gancho por encima de la media: reutiliza este inicio","En la media de la campaña"))))) -> Pocos datos todavía | AC6: =IF(M6>0,T6+ROW()/1000000,-1000000+ROW()) -> -3.369994
A7: 120254996414630271 | B7: PIXARVENTA_H1 | C7: CeraLux ES — Test 3 ángulos — Oct 2026 | D7: AS2 · DINERO — voy a vender el coche | E7: C2 | F7: Animación estilo Pixar (habla el bote) | G7: Texto | H7: Vender el coche | I7: Vas a vender tu coche esta semana y esos rayones van a decidir lo que te ofrecen. No merece la pena, ¿no? | J7: 46300 | K7: Activo | M7: =SUMIFS(Histórico!$F$5:$F$5000,Histórico!$B$5:$B$5000,$A7,Histórico!$A$5:$A$5000,">="&DESDE,Histórico!$A$5:$A$5000,"<="&HASTA) -> 9.17 | N7: =SUMIFS(Histórico!$G$5:$G$5000,Histórico!$B$5:$B$5000,$A7,Histórico!$A$5:$A$5000,">="&DESDE,Histórico!$A$5:$A$5000,"<="&HASTA) -> 627 | O7: =SUMIFS(Histórico!$H$5:$H$5000,Histórico!$B$5:$B$5000,$A7,Histórico!$A$5:$A$5000,">="&DESDE,Histórico!$A$5:$A$5000,"<="&HASTA) -> 23 | P7: =SUMIFS(Histórico!$I$5:$I$5000,Histórico!$B$5:$B$5000,$A7,Histórico!$A$5:$A$5000,">="&DESDE,Histórico!$A$5:$A$5000,"<="&HASTA) -> 10 | Q7: =SUMIFS(Histórico!$L$5:$L$5000,Histórico!$B$5:$B$5000,$A7,Histórico!$A$5:$A$5000,">="&DESDE,Histórico!$A$5:$A$5000,"<="&HASTA) -> 0 | R7: =Q7*RATIO -> 0 | S7: =IF(R7>0,M7/R7,"") | T7: =R7*BEN_PEDIDO-M7*(1+RECARGO) -> -9.17 | U7: =IF(N7>0,SUMIFS(Histórico!$M$5:$M$5000,Histórico!$B$5:$B$5000,$A7,Histórico!$A$5:$A$5000,">="&DESDE,Histórico!$A$5:$A$5000,"<="&HASTA)/N7,"") -> 0.19457735 | V7: =IF(SUMIFS(Histórico!$M$5:$M$5000,Histórico!$B$5:$B$5000,$A7,Histórico!$A$5:$A$5000,">="&DESDE,Histórico!$A$5:$A$5000,"<="&HASTA)>0,SUMIFS(Histórico!$N$5:$N$5000,Histórico!$B$5:$B$5000,$A7,Histórico!$A$5:$A$5000,">="&DESDE,Histórico!$A$5:$A$5000,"<="&HASTA)/SUMIFS(Histórico!$M$5:$M$5000,Histórico!$B$5:$B$5000,$A7,Histórico!$A$5:$A$5000,">="&DESDE,Histórico!$A$5:$A$5000,"<="&HASTA),"") -> 0.66393443 | W7: =IF(N7>0,O7/N7,"") -> 0.036682616 | X7: =IF(O7>0,P7/O7,"") -> 0.43478261 | Y7: =IF(O7>0,Q7/O7,"") -> 0 | Z7: =IF(N7>0,SUMIFS(Histórico!$T$5:$T$5000,Histórico!$B$5:$B$5000,$A7,Histórico!$A$5:$A$5000,">="&DESDE,Histórico!$A$5:$A$5000,"<="&HASTA)/N7,"") -> 7.0398724 | AA7: =IF(M7=0,"SIN GASTO",IF(Q7=0,IF(M7>=APG_SV*CPA_BE,"APAGAR",IF(M7>=0.5*CPA_BE,"VIGILAR","APRENDIENDO")),IF(AND(S7<=UMB_ESC*CPA_BE,Q7>=3),"ESCALAR",IF(AND(S7<=CPA_BE,Q7>=3),"MANTENER",IF(S7<=CPA_BE,"PROMETEDOR",IF(M7>=APG_CV*CPA_BE,"APAGAR","VIGILAR")))))) -> VIGILAR | AB7: =IF(N7<MIN_IMPR,"Pocos datos todavía",IF(AND(ISNUMBER(U7),U7<0.7*MEDIA_GANCHO),"Gancho flojo: cambia los 3 primeros segundos",IF(AND(ISNUMBER(W7),W7<0.7*MEDIA_CTR),"Enganchan pero no hacen clic: refuerza oferta y llamada a la acción",IF(AND(O7>=20,ISNUMBER(Y7),Y7<0.6*MEDIA_CVR),"Hacen clic pero no compran: revisa ángulo y página",IF(AND(ISNUMBER(U7),U7>=1.3*MEDIA_GANCHO),"Gancho por encima de la media: reutiliza este inicio","En la media de la campaña"))))) -> Pocos datos todavía | AC7: =IF(M7>0,T7+ROW()/1000000,-1000000+ROW()) -> -9.169993
A8: 120254996416070271 | B8: PIXARVENTA_H2 | C8: CeraLux ES — Test 3 ángulos — Oct 2026 | D8: AS2 · DINERO — voy a vender el coche | E8: C2 | F8: Animación estilo Pixar (habla el bote) | G8: Texto | H8: Vender el coche | I8: Vas a vender el coche y esos cuatro rayones le van a dar la excusa perfecta para bajarte el precio. | J8: 46300 | K8: Activo | M8: =SUMIFS(Histórico!$F$5:$F$5000,Histórico!$B$5:$B$5000,$A8,Histórico!$A$5:$A$5000,">="&DESDE,Histórico!$A$5:$A$5000,"<="&HASTA) -> 2.35 | N8: =SUMIFS(Histórico!$G$5:$G$5000,Histórico!$B$5:$B$5000,$A8,Histórico!$A$5:$A$5000,">="&DESDE,Histórico!$A$5:$A$5000,"<="&HASTA) -> 232 | O8: =SUMIFS(Histórico!$H$5:$H$5000,Histórico!$B$5:$B$5000,$A8,Histórico!$A$5:$A$5000,">="&DESDE,Histórico!$A$5:$A$5000,"<="&HASTA) -> 6 | P8: =SUMIFS(Histórico!$I$5:$I$5000,Histórico!$B$5:$B$5000,$A8,Histórico!$A$5:$A$5000,">="&DESDE,Histórico!$A$5:$A$5000,"<="&HASTA) -> 0 | Q8: =SUMIFS(Histórico!$L$5:$L$5000,Histórico!$B$5:$B$5000,$A8,Histórico!$A$5:$A$5000,">="&DESDE,Histórico!$A$5:$A$5000,"<="&HASTA) -> 0 | R8: =Q8*RATIO -> 0 | S8: =IF(R8>0,M8/R8,"") | T8: =R8*BEN_PEDIDO-M8*(1+RECARGO) -> -2.35 | U8: =IF(N8>0,SUMIFS(Histórico!$M$5:$M$5000,Histórico!$B$5:$B$5000,$A8,Histórico!$A$5:$A$5000,">="&DESDE,Histórico!$A$5:$A$5000,"<="&HASTA)/N8,"") -> 0.1637931 | V8: =IF(SUMIFS(Histórico!$M$5:$M$5000,Histórico!$B$5:$B$5000,$A8,Histórico!$A$5:$A$5000,">="&DESDE,Histórico!$A$5:$A$5000,"<="&HASTA)>0,SUMIFS(Histórico!$N$5:$N$5000,Histórico!$B$5:$B$5000,$A8,Histórico!$A$5:$A$5000,">="&DESDE,Histórico!$A$5:$A$5000,"<="&HASTA)/SUMIFS(Histórico!$M$5:$M$5000,Histórico!$B$5:$B$5000,$A8,Histórico!$A$5:$A$5000,">="&DESDE,Histórico!$A$5:$A$5000,"<="&HASTA),"") -> 0.63157895 | W8: =IF(N8>0,O8/N8,"") -> 0.025862069 | X8: =IF(O8>0,P8/O8,"") -> 0 | Y8: =IF(O8>0,Q8/O8,"") -> 0 | Z8: =IF(N8>0,SUMIFS(Histórico!$T$5:$T$5000,Histórico!$B$5:$B$5000,$A8,Histórico!$A$5:$A$5000,">="&DESDE,Histórico!$A$5:$A$5000,"<="&HASTA)/N8,"") -> 6.4267241 | AA8: =IF(M8=0,"SIN GASTO",IF(Q8=0,IF(M8>=APG_SV*CPA_BE,"APAGAR",IF(M8>=0.5*CPA_BE,"VIGILAR","APRENDIENDO")),IF(AND(S8<=UMB_ESC*CPA_BE,Q8>=3),"ESCALAR",IF(AND(S8<=CPA_BE,Q8>=3),"MANTENER",IF(S8<=CPA_BE,"PROMETEDOR",IF(M8>=APG_CV*CPA_BE,"APAGAR","VIGILAR")))))) -> APRENDIENDO | AB8: =IF(N8<MIN_IMPR,"Pocos datos todavía",IF(AND(ISNUMBER(U8),U8<0.7*MEDIA_GANCHO),"Gancho flojo: cambia los 3 primeros segundos",IF(AND(ISNUMBER(W8),W8<0.7*MEDIA_CTR),"Enganchan pero no hacen clic: refuerza oferta y llamada a la acción",IF(AND(O8>=20,ISNUMBER(Y8),Y8<0.6*MEDIA_CVR),"Hacen clic pero no compran: revisa ángulo y página",IF(AND(ISNUMBER(U8),U8>=1.3*MEDIA_GANCHO),"Gancho por encima de la media: reutiliza este inicio","En la media de la campaña"))))) -> Pocos datos todavía | AC8: =IF(M8>0,T8+ROW()/1000000,-1000000+ROW()) -> -2.349992
A9: 120254996454750271 | B9: PIXARVENTA_H3 | C9: CeraLux ES — Test 3 ángulos — Oct 2026 | D9: AS2 · DINERO — voy a vender el coche | E9: C2 | F9: Animación estilo Pixar (habla el bote) | G9: Texto | H9: Vender el coche | I9: Siempre has mimado tu coche y ahora que lo vendes, te van a regatear por cuatro rayones que ni son tuyos. | J9: 46300 | K9: Activo | M9: =SUMIFS(Histórico!$F$5:$F$5000,Histórico!$B$5:$B$5000,$A9,Histórico!$A$5:$A$5000,">="&DESDE,Histórico!$A$5:$A$5000,"<="&HASTA) -> 2.84 | N9: =SUMIFS(Histórico!$G$5:$G$5000,Histórico!$B$5:$B$5000,$A9,Histórico!$A$5:$A$5000,">="&DESDE,Histórico!$A$5:$A$5000,"<="&HASTA) -> 220 | O9: =SUMIFS(Histórico!$H$5:$H$5000,Histórico!$B$5:$B$5000,$A9,Histórico!$A$5:$A$5000,">="&DESDE,Histórico!$A$5:$A$5000,"<="&HASTA) -> 5 | P9: =SUMIFS(Histórico!$I$5:$I$5000,Histórico!$B$5:$B$5000,$A9,Histórico!$A$5:$A$5000,">="&DESDE,Histórico!$A$5:$A$5000,"<="&HASTA) -> 1 | Q9: =SUMIFS(Histórico!$L$5:$L$5000,Histórico!$B$5:$B$5000,$A9,Histórico!$A$5:$A$5000,">="&DESDE,Histórico!$A$5:$A$5000,"<="&HASTA) -> 0 | R9: =Q9*RATIO -> 0 | S9: =IF(R9>0,M9/R9,"") | T9: =R9*BEN_PEDIDO-M9*(1+RECARGO) -> -2.84 | U9: =IF(N9>0,SUMIFS(Histórico!$M$5:$M$5000,Histórico!$B$5:$B$5000,$A9,Histórico!$A$5:$A$5000,">="&DESDE,Histórico!$A$5:$A$5000,"<="&HASTA)/N9,"") -> 0.21818182 | V9: =IF(SUMIFS(Histórico!$M$5:$M$5000,Histórico!$B$5:$B$5000,$A9,Histórico!$A$5:$A$5000,">="&DESDE,Histórico!$A$5:$A$5000,"<="&HASTA)>0,SUMIFS(Histórico!$N$5:$N$5000,Histórico!$B$5:$B$5000,$A9,Histórico!$A$5:$A$5000,">="&DESDE,Histórico!$A$5:$A$5000,"<="&HASTA)/SUMIFS(Histórico!$M$5:$M$5000,Histórico!$B$5:$B$5000,$A9,Histórico!$A$5:$A$5000,">="&DESDE,Histórico!$A$5:$A$5000,"<="&HASTA),"") -> 0.58333333 | W9: =IF(N9>0,O9/N9,"") -> 0.022727273 | X9: =IF(O9>0,P9/O9,"") -> 0.2 | Y9: =IF(O9>0,Q9/O9,"") -> 0 | Z9: =IF(N9>0,SUMIFS(Histórico!$T$5:$T$5000,Histórico!$B$5:$B$5000,$A9,Histórico!$A$5:$A$5000,">="&DESDE,Histórico!$A$5:$A$5000,"<="&HASTA)/N9,"") -> 7.2090909 | AA9: =IF(M9=0,"SIN GASTO",IF(Q9=0,IF(M9>=APG_SV*CPA_BE,"APAGAR",IF(M9>=0.5*CPA_BE,"VIGILAR","APRENDIENDO")),IF(AND(S9<=UMB_ESC*CPA_BE,Q9>=3),"ESCALAR",IF(AND(S9<=CPA_BE,Q9>=3),"MANTENER",IF(S9<=CPA_BE,"PROMETEDOR",IF(M9>=APG_CV*CPA_BE,"APAGAR","VIGILAR")))))) -> APRENDIENDO | AB9: =IF(N9<MIN_IMPR,"Pocos datos todavía",IF(AND(ISNUMBER(U9),U9<0.7*MEDIA_GANCHO),"Gancho flojo: cambia los 3 primeros segundos",IF(AND(ISNUMBER(W9),W9<0.7*MEDIA_CTR),"Enganchan pero no hacen clic: refuerza oferta y llamada a la acción",IF(AND(O9>=20,ISNUMBER(Y9),Y9<0.6*MEDIA_CVR),"Hacen clic pero no compran: revisa ángulo y página",IF(AND(ISNUMBER(U9),U9>=1.3*MEDIA_GANCHO),"Gancho por encima de la media: reutiliza este inicio","En la media de la campaña"))))) -> Pocos datos todavía | AC9: =IF(M9>0,T9+ROW()/1000000,-1000000+ROW()) -> -2.839991
A10: 120254996458790271 | B10: BROAD_H1 BOLARDO | C10: CeraLux ES — Test 3 ángulos — Oct 2026 | D10: AS3 · BROAD — hooks visuales | E10: C3 | F10: Demostración real (UGC) | G10: Visual | H10: Bolardo | J10: 46300 | K10: Activo | M10: =SUMIFS(Histórico!$F$5:$F$5000,Histórico!$B$5:$B$5000,$A10,Histórico!$A$5:$A$5000,">="&DESDE,Histórico!$A$5:$A$5000,"<="&HASTA) -> 85.54 | N10: =SUMIFS(Histórico!$G$5:$G$5000,Histórico!$B$5:$B$5000,$A10,Histórico!$A$5:$A$5000,">="&DESDE,Histórico!$A$5:$A$5000,"<="&HASTA) -> 14164 | O10: =SUMIFS(Histórico!$H$5:$H$5000,Histórico!$B$5:$B$5000,$A10,Histórico!$A$5:$A$5000,">="&DESDE,Histórico!$A$5:$A$5000,"<="&HASTA) -> 228 | P10: =SUMIFS(Histórico!$I$5:$I$5000,Histórico!$B$5:$B$5000,$A10,Histórico!$A$5:$A$5000,">="&DESDE,Histórico!$A$5:$A$5000,"<="&HASTA) -> 86 | Q10: =SUMIFS(Histórico!$L$5:$L$5000,Histórico!$B$5:$B$5000,$A10,Histórico!$A$5:$A$5000,">="&DESDE,Histórico!$A$5:$A$5000,"<="&HASTA) -> 10 | R10: =Q10*RATIO -> 10.47619 | S10: =IF(R10>0,M10/R10,"") -> 8.1651818 | T10: =R10*BEN_PEDIDO-M10*(1+RECARGO) -> 37.66 | U10: =IF(N10>0,SUMIFS(Histórico!$M$5:$M$5000,Histórico!$B$5:$B$5000,$A10,Histórico!$A$5:$A$5000,">="&DESDE,Histórico!$A$5:$A$5000,"<="&HASTA)/N10,"") -> 0.12108162 | V10: =IF(SUMIFS(Histórico!$M$5:$M$5000,Histórico!$B$5:$B$5000,$A10,Histórico!$A$5:$A$5000,">="&DESDE,Histórico!$A$5:$A$5000,"<="&HASTA)>0,SUMIFS(Histórico!$N$5:$N$5000,Histórico!$B$5:$B$5000,$A10,Histórico!$A$5:$A$5000,">="&DESDE,Histórico!$A$5:$A$5000,"<="&HASTA)/SUMIFS(Histórico!$M$5:$M$5000,Histórico!$B$5:$B$5000,$A10,Histórico!$A$5:$A$5000,">="&DESDE,Histórico!$A$5:$A$5000,"<="&HASTA),"") -> 0.51137026 | W10: =IF(N10>0,O10/N10,"") -> 0.016097148 | X10: =IF(O10>0,P10/O10,"") -> 0.37719298 | Y10: =IF(O10>0,Q10/O10,"") -> 0.043859649 | Z10: =IF(N10>0,SUMIFS(Histórico!$T$5:$T$5000,Histórico!$B$5:$B$5000,$A10,Histórico!$A$5:$A$5000,">="&DESDE,Histórico!$A$5:$A$5000,"<="&HASTA)/N10,"") -> 4 | AA10: =IF(M10=0,"SIN GASTO",IF(Q10=0,IF(M10>=APG_SV*CPA_BE,"APAGAR",IF(M10>=0.5*CPA_BE,"VIGILAR","APRENDIENDO")),IF(AND(S10<=UMB_ESC*CPA_BE,Q10>=3),"ESCALAR",IF(AND(S10<=CPA_BE,Q10>=3),"MANTENER",IF(S10<=CPA_BE,"PROMETEDOR",IF(M10>=APG_CV*CPA_BE,"APAGAR","VIGILAR")))))) -> ESCALAR | AB10: =IF(N10<MIN_IMPR,"Pocos datos todavía",IF(AND(ISNUMBER(U10),U10<0.7*MEDIA_GANCHO),"Gancho flojo: cambia los 3 primeros segundos",IF(AND(ISNUMBER(W10),W10<0.7*MEDIA_CTR),"Enganchan pero no hacen clic: refuerza oferta y llamada a la acción",IF(AND(O10>=20,ISNUMBER(Y10),Y10<0.6*MEDIA_CVR),"Hacen clic pero no compran: revisa ángulo y página",IF(AND(ISNUMBER(U10),U10>=1.3*MEDIA_GANCHO),"Gancho por encima de la media: reutiliza este inicio","En la media de la campaña"))))) -> En la media de la campaña | AC10: =IF(M10>0,T10+ROW()/1000000,-1000000+ROW()) -> 37.66001
A11: 120254996458800271 | B11: BROAD_H2 LLAVES | C11: CeraLux ES — Test 3 ángulos — Oct 2026 | D11: AS3 · BROAD — hooks visuales | E11: C3 | F11: Demostración real (UGC) | G11: Visual | H11: Llaves | J11: 46300 | K11: Activo | M11: =SUMIFS(Histórico!$F$5:$F$5000,Histórico!$B$5:$B$5000,$A11,Histórico!$A$5:$A$5000,">="&DESDE,Histórico!$A$5:$A$5000,"<="&HASTA) -> 37.7 | N11: =SUMIFS(Histórico!$G$5:$G$5000,Histórico!$B$5:$B$5000,$A11,Histórico!$A$5:$A$5000,">="&DESDE,Histórico!$A$5:$A$5000,"<="&HASTA) -> 3992 | O11: =SUMIFS(Histórico!$H$5:$H$5000,Histórico!$B$5:$B$5000,$A11,Histórico!$A$5:$A$5000,">="&DESDE,Histórico!$A$5:$A$5000,"<="&HASTA) -> 74 | P11: =SUMIFS(Histórico!$I$5:$I$5000,Histórico!$B$5:$B$5000,$A11,Histórico!$A$5:$A$5000,">="&DESDE,Histórico!$A$5:$A$5000,"<="&HASTA) -> 31 | Q11: =SUMIFS(Histórico!$L$5:$L$5000,Histórico!$B$5:$B$5000,$A11,Histórico!$A$5:$A$5000,">="&DESDE,Histórico!$A$5:$A$5000,"<="&HASTA) -> 6 | R11: =Q11*RATIO -> 6.2857143 | S11: =IF(R11>0,M11/R11,"") -> 5.9977273 | T11: =R11*BEN_PEDIDO-M11*(1+RECARGO) -> 36.22 | U11: =IF(N11>0,SUMIFS(Histórico!$M$5:$M$5000,Histórico!$B$5:$B$5000,$A11,Histórico!$A$5:$A$5000,">="&DESDE,Histórico!$A$5:$A$5000,"<="&HASTA)/N11,"") -> 0.10896794 | V11: =IF(SUMIFS(Histórico!$M$5:$M$5000,Histórico!$B$5:$B$5000,$A11,Histórico!$A$5:$A$5000,">="&DESDE,Histórico!$A$5:$A$5000,"<="&HASTA)>0,SUMIFS(Histórico!$N$5:$N$5000,Histórico!$B$5:$B$5000,$A11,Histórico!$A$5:$A$5000,">="&DESDE,Histórico!$A$5:$A$5000,"<="&HASTA)/SUMIFS(Histórico!$M$5:$M$5000,Histórico!$B$5:$B$5000,$A11,Histórico!$A$5:$A$5000,">="&DESDE,Histórico!$A$5:$A$5000,"<="&HASTA),"") -> 0.45977011 | W11: =IF(N11>0,O11/N11,"") -> 0.018537074 | X11: =IF(O11>0,P11/O11,"") -> 0.41891892 | Y11: =IF(O11>0,Q11/O11,"") -> 0.081081081 | Z11: =IF(N11>0,SUMIFS(Histórico!$T$5:$T$5000,Histórico!$B$5:$B$5000,$A11,Histórico!$A$5:$A$5000,">="&DESDE,Histórico!$A$5:$A$5000,"<="&HASTA)/N11,"") -> 3.8717435 | AA11: =IF(M11=0,"SIN GASTO",IF(Q11=0,IF(M11>=APG_SV*CPA_BE,"APAGAR",IF(M11>=0.5*CPA_BE,"VIGILAR","APRENDIENDO")),IF(AND(S11<=UMB_ESC*CPA_BE,Q11>=3),"ESCALAR",IF(AND(S11<=CPA_BE,Q11>=3),"MANTENER",IF(S11<=CPA_BE,"PROMETEDOR",IF(M11>=APG_CV*CPA_BE,"APAGAR","VIGILAR")))))) -> ESCALAR | AB11: =IF(N11<MIN_IMPR,"Pocos datos todavía",IF(AND(ISNUMBER(U11),U11<0.7*MEDIA_GANCHO),"Gancho flojo: cambia los 3 primeros segundos",IF(AND(ISNUMBER(W11),W11<0.7*MEDIA_CTR),"Enganchan pero no hacen clic: refuerza oferta y llamada a la acción",IF(AND(O11>=20,ISNUMBER(Y11),Y11<0.6*MEDIA_CVR),"Hacen clic pero no compran: revisa ángulo y página",IF(AND(ISNUMBER(U11),U11>=1.3*MEDIA_GANCHO),"Gancho por encima de la media: reutiliza este inicio","En la media de la campaña"))))) -> En la media de la campaña | AC11: =IF(M11>0,T11+ROW()/1000000,-1000000+ROW()) -> 36.220011
A12: 120254996458810271 | B12: BROAD_H3 LLAVES | C12: CeraLux ES — Test 3 ángulos — Oct 2026 | D12: AS3 · BROAD — hooks visuales | E12: C3 | F12: Demostración real (UGC) | G12: Visual | H12: Llaves | J12: 46300 | K12: Activo | M12: =SUMIFS(Histórico!$F$5:$F$5000,Histórico!$B$5:$B$5000,$A12,Histórico!$A$5:$A$5000,">="&DESDE,Histórico!$A$5:$A$5000,"<="&HASTA) -> 1.81 | N12: =SUMIFS(Histórico!$G$5:$G$5000,Histórico!$B$5:$B$5000,$A12,Histórico!$A$5:$A$5000,">="&DESDE,Histórico!$A$5:$A$5000,"<="&HASTA) -> 157 | O12: =SUMIFS(Histórico!$H$5:$H$5000,Histórico!$B$5:$B$5000,$A12,Histórico!$A$5:$A$5000,">="&DESDE,Histórico!$A$5:$A$5000,"<="&HASTA) -> 3 | P12: =SUMIFS(Histórico!$I$5:$I$5000,Histórico!$B$5:$B$5000,$A12,Histórico!$A$5:$A$5000,">="&DESDE,Histórico!$A$5:$A$5000,"<="&HASTA) -> 3 | Q12: =SUMIFS(Histórico!$L$5:$L$5000,Histórico!$B$5:$B$5000,$A12,Histórico!$A$5:$A$5000,">="&DESDE,Histórico!$A$5:$A$5000,"<="&HASTA) -> 0 | R12: =Q12*RATIO -> 0 | S12: =IF(R12>0,M12/R12,"") | T12: =R12*BEN_PEDIDO-M12*(1+RECARGO) -> -1.81 | U12: =IF(N12>0,SUMIFS(Histórico!$M$5:$M$5000,Histórico!$B$5:$B$5000,$A12,Histórico!$A$5:$A$5000,">="&DESDE,Histórico!$A$5:$A$5000,"<="&HASTA)/N12,"") -> 0.1656051 | V12: =IF(SUMIFS(Histórico!$M$5:$M$5000,Histórico!$B$5:$B$5000,$A12,Histórico!$A$5:$A$5000,">="&DESDE,Histórico!$A$5:$A$5000,"<="&HASTA)>0,SUMIFS(Histórico!$N$5:$N$5000,Histórico!$B$5:$B$5000,$A12,Histórico!$A$5:$A$5000,">="&DESDE,Histórico!$A$5:$A$5000,"<="&HASTA)/SUMIFS(Histórico!$M$5:$M$5000,Histórico!$B$5:$B$5000,$A12,Histórico!$A$5:$A$5000,">="&DESDE,Histórico!$A$5:$A$5000,"<="&HASTA),"") -> 0.5 | W12: =IF(N12>0,O12/N12,"") -> 0.01910828 | X12: =IF(O12>0,P12/O12,"") -> 1 | Y12: =IF(O12>0,Q12/O12,"") -> 0 | Z12: =IF(N12>0,SUMIFS(Histórico!$T$5:$T$5000,Histórico!$B$5:$B$5000,$A12,Histórico!$A$5:$A$5000,">="&DESDE,Histórico!$A$5:$A$5000,"<="&HASTA)/N12,"") -> 4.9235669 | AA12: =IF(M12=0,"SIN GASTO",IF(Q12=0,IF(M12>=APG_SV*CPA_BE,"APAGAR",IF(M12>=0.5*CPA_BE,"VIGILAR","APRENDIENDO")),IF(AND(S12<=UMB_ESC*CPA_BE,Q12>=3),"ESCALAR",IF(AND(S12<=CPA_BE,Q12>=3),"MANTENER",IF(S12<=CPA_BE,"PROMETEDOR",IF(M12>=APG_CV*CPA_BE,"APAGAR","VIGILAR")))))) -> APRENDIENDO | AB12: =IF(N12<MIN_IMPR,"Pocos datos todavía",IF(AND(ISNUMBER(U12),U12<0.7*MEDIA_GANCHO),"Gancho flojo: cambia los 3 primeros segundos",IF(AND(ISNUMBER(W12),W12<0.7*MEDIA_CTR),"Enganchan pero no hacen clic: refuerza oferta y llamada a la acción",IF(AND(O12>=20,ISNUMBER(Y12),Y12<0.6*MEDIA_CVR),"Hacen clic pero no compran: revisa ángulo y página",IF(AND(ISNUMBER(U12),U12>=1.3*MEDIA_GANCHO),"Gancho por encima de la media: reutiliza este inicio","En la media de la campaña"))))) -> Pocos datos todavía | AC12: =IF(M12>0,T12+ROW()/1000000,-1000000+ROW()) -> -1.809988
A13: 120254996458820271 | B13: BROAD_H4 PERRO | C13: CeraLux ES — Test 3 ángulos — Oct 2026 | D13: AS3 · BROAD — hooks visuales | E13: C3 | F13: Demostración real (UGC) | G13: Visual | H13: Perro | J13: 46300 | K13: Activo | M13: =SUMIFS(Histórico!$F$5:$F$5000,Histórico!$B$5:$B$5000,$A13,Histórico!$A$5:$A$5000,">="&DESDE,Histórico!$A$5:$A$5000,"<="&HASTA) -> 8.45 | N13: =SUMIFS(Histórico!$G$5:$G$5000,Histórico!$B$5:$B$5000,$A13,Histórico!$A$5:$A$5000,">="&DESDE,Histórico!$A$5:$A$5000,"<="&HASTA) -> 754 | O13: =SUMIFS(Histórico!$H$5:$H$5000,Histórico!$B$5:$B$5000,$A13,Histórico!$A$5:$A$5000,">="&DESDE,Histórico!$A$5:$A$5000,"<="&HASTA) -> 19 | P13: =SUMIFS(Histórico!$I$5:$I$5000,Histórico!$B$5:$B$5000,$A13,Histórico!$A$5:$A$5000,">="&DESDE,Histórico!$A$5:$A$5000,"<="&HASTA) -> 6 | Q13: =SUMIFS(Histórico!$L$5:$L$5000,Histórico!$B$5:$B$5000,$A13,Histórico!$A$5:$A$5000,">="&DESDE,Histórico!$A$5:$A$5000,"<="&HASTA) -> 2 | R13: =Q13*RATIO -> 2.0952381 | S13: =IF(R13>0,M13/R13,"") -> 4.0329545 | T13: =R13*BEN_PEDIDO-M13*(1+RECARGO) -> 16.19 | U13: =IF(N13>0,SUMIFS(Histórico!$M$5:$M$5000,Histórico!$B$5:$B$5000,$A13,Histórico!$A$5:$A$5000,">="&DESDE,Histórico!$A$5:$A$5000,"<="&HASTA)/N13,"") -> 0.18567639 | V13: =IF(SUMIFS(Histórico!$M$5:$M$5000,Histórico!$B$5:$B$5000,$A13,Histórico!$A$5:$A$5000,">="&DESDE,Histórico!$A$5:$A$5000,"<="&HASTA)>0,SUMIFS(Histórico!$N$5:$N$5000,Histórico!$B$5:$B$5000,$A13,Histórico!$A$5:$A$5000,">="&DESDE,Histórico!$A$5:$A$5000,"<="&HASTA)/SUMIFS(Histórico!$M$5:$M$5000,Histórico!$B$5:$B$5000,$A13,Histórico!$A$5:$A$5000,">="&DESDE,Histórico!$A$5:$A$5000,"<="&HASTA),"") -> 0.50714286 | W13: =IF(N13>0,O13/N13,"") -> 0.025198939 | X13: =IF(O13>0,P13/O13,"") -> 0.31578947 | Y13: =IF(O13>0,Q13/O13,"") -> 0.10526316 | Z13: =IF(N13>0,SUMIFS(Histórico!$T$5:$T$5000,Histórico!$B$5:$B$5000,$A13,Histórico!$A$5:$A$5000,">="&DESDE,Histórico!$A$5:$A$5000,"<="&HASTA)/N13,"") -> 5.3793103 | AA13: =IF(M13=0,"SIN GASTO",IF(Q13=0,IF(M13>=APG_SV*CPA_BE,"APAGAR",IF(M13>=0.5*CPA_BE,"VIGILAR","APRENDIENDO")),IF(AND(S13<=UMB_ESC*CPA_BE,Q13>=3),"ESCALAR",IF(AND(S13<=CPA_BE,Q13>=3),"MANTENER",IF(S13<=CPA_BE,"PROMETEDOR",IF(M13>=APG_CV*CPA_BE,"APAGAR","VIGILAR")))))) -> PROMETEDOR | AB13: =IF(N13<MIN_IMPR,"Pocos datos todavía",IF(AND(ISNUMBER(U13),U13<0.7*MEDIA_GANCHO),"Gancho flojo: cambia los 3 primeros segundos",IF(AND(ISNUMBER(W13),W13<0.7*MEDIA_CTR),"Enganchan pero no hacen clic: refuerza oferta y llamada a la acción",IF(AND(O13>=20,ISNUMBER(Y13),Y13<0.6*MEDIA_CVR),"Hacen clic pero no compran: revisa ángulo y página",IF(AND(ISNUMBER(U13),U13>=1.3*MEDIA_GANCHO),"Gancho por encima de la media: reutiliza este inicio","En la media de la campaña"))))) -> Pocos datos todavía | AC13: =IF(M13>0,T13+ROW()/1000000,-1000000+ROW()) -> 16.190013
A14: 120254996458830271 | B14: BROAD_H5 PERRO | C14: CeraLux ES — Test 3 ángulos — Oct 2026 | D14: AS3 · BROAD — hooks visuales | E14: C3 | F14: Demostración real (UGC) | G14: Visual | H14: Perro | J14: 46300 | K14: Activo | M14: =SUMIFS(Histórico!$F$5:$F$5000,Histórico!$B$5:$B$5000,$A14,Histórico!$A$5:$A$5000,">="&DESDE,Histórico!$A$5:$A$5000,"<="&HASTA) -> 0.05 | N14: =SUMIFS(Histórico!$G$5:$G$5000,Histórico!$B$5:$B$5000,$A14,Histórico!$A$5:$A$5000,">="&DESDE,Histórico!$A$5:$A$5000,"<="&HASTA) -> 13 | O14: =SUMIFS(Histórico!$H$5:$H$5000,Histórico!$B$5:$B$5000,$A14,Histórico!$A$5:$A$5000,">="&DESDE,Histórico!$A$5:$A$5000,"<="&HASTA) -> 0 | P14: =SUMIFS(Histórico!$I$5:$I$5000,Histórico!$B$5:$B$5000,$A14,Histórico!$A$5:$A$5000,">="&DESDE,Histórico!$A$5:$A$5000,"<="&HASTA) -> 0 | Q14: =SUMIFS(Histórico!$L$5:$L$5000,Histórico!$B$5:$B$5000,$A14,Histórico!$A$5:$A$5000,">="&DESDE,Histórico!$A$5:$A$5000,"<="&HASTA) -> 0 | R14: =Q14*RATIO -> 0 | S14: =IF(R14>0,M14/R14,"") | T14: =R14*BEN_PEDIDO-M14*(1+RECARGO) -> -0.05 | U14: =IF(N14>0,SUMIFS(Histórico!$M$5:$M$5000,Histórico!$B$5:$B$5000,$A14,Histórico!$A$5:$A$5000,">="&DESDE,Histórico!$A$5:$A$5000,"<="&HASTA)/N14,"") -> 0 | V14: =IF(SUMIFS(Histórico!$M$5:$M$5000,Histórico!$B$5:$B$5000,$A14,Histórico!$A$5:$A$5000,">="&DESDE,Histórico!$A$5:$A$5000,"<="&HASTA)>0,SUMIFS(Histórico!$N$5:$N$5000,Histórico!$B$5:$B$5000,$A14,Histórico!$A$5:$A$5000,">="&DESDE,Histórico!$A$5:$A$5000,"<="&HASTA)/SUMIFS(Histórico!$M$5:$M$5000,Histórico!$B$5:$B$5000,$A14,Histórico!$A$5:$A$5000,">="&DESDE,Histórico!$A$5:$A$5000,"<="&HASTA),"") | W14: =IF(N14>0,O14/N14,"") -> 0 | X14: =IF(O14>0,P14/O14,"") | Y14: =IF(O14>0,Q14/O14,"") | Z14: =IF(N14>0,SUMIFS(Histórico!$T$5:$T$5000,Histórico!$B$5:$B$5000,$A14,Histórico!$A$5:$A$5000,">="&DESDE,Histórico!$A$5:$A$5000,"<="&HASTA)/N14,"") -> 2 | AA14: =IF(M14=0,"SIN GASTO",IF(Q14=0,IF(M14>=APG_SV*CPA_BE,"APAGAR",IF(M14>=0.5*CPA_BE,"VIGILAR","APRENDIENDO")),IF(AND(S14<=UMB_ESC*CPA_BE,Q14>=3),"ESCALAR",IF(AND(S14<=CPA_BE,Q14>=3),"MANTENER",IF(S14<=CPA_BE,"PROMETEDOR",IF(M14>=APG_CV*CPA_BE,"APAGAR","VIGILAR")))))) -> APRENDIENDO | AB14: =IF(N14<MIN_IMPR,"Pocos datos todavía",IF(AND(ISNUMBER(U14),U14<0.7*MEDIA_GANCHO),"Gancho flojo: cambia los 3 primeros segundos",IF(AND(ISNUMBER(W14),W14<0.7*MEDIA_CTR),"Enganchan pero no hacen clic: refuerza oferta y llamada a la acción",IF(AND(O14>=20,ISNUMBER(Y14),Y14<0.6*MEDIA_CVR),"Hacen clic pero no compran: revisa ángulo y página",IF(AND(ISNUMBER(U14),U14>=1.3*MEDIA_GANCHO),"Gancho por encima de la media: reutiliza este inicio","En la media de la campaña"))))) -> Pocos datos todavía | AC14: =IF(M14>0,T14+ROW()/1000000,-1000000+ROW()) -> -0.049986
